Workbook

Sheet Read Me
A1: TSSRA Open-Source AI Pilot - Read Me
A3: Purpose | B3: Exploratory, open-source pilot covering every outcome family and consequence target archetype supplied by the user.
A4: Status | B4: Illustrative analytic pilot. It is not an approved TSSRA estimate, threat assessment, operational plan, or substitute for DHS/SRAD judgment.
A5: Security boundary | B5: No actual TSSRA scenario data or nonpublic information was used. Internal data should be inserted only in the DHS-approved Chat environment.
A6: Output interpretation | B6: P10/P50/P90 values are conditional consequences assuming the specified event occurs. They are not annual probabilities or expected annual loss.
A7: Outcome module | B7: Monetizes fatalities, injuries, and property damage for all 16 listed 9.0 outcome families.
A8: Consequence module | B8: Estimates first-order and second-order costs for five target archetypes across seven outage durations.
A9: Injury valuation | B9: Uses scenario-specific average MAIS fractions. Replace them with observed severity distributions when available.
A10: Indirect impacts | B10: Uses generic daily loss ranges and cross-sector allocation shares. Replace with asset-specific BEA/RIMS II, FAF, operational, and dependency inputs.
A11: Confidence | B11: High = multiple directly comparable official observations; Moderate = relevant observations with adjustment; Low = sparse data, analogy, or mechanistic modeling.
A12: Key definition | B12: IID is provisionally interpreted as improvised incendiary device. Confirm the intended TSSRA definition before use.
A13: Version | B13: Pilot 1.5 (2026-dollar escalation + cross-sector impacts view) generated 2026-08-03
A15: Recommended workflow: validate definitions -> replace generic target parameters -> validate source incidents -> run sensitivity review -> obtain SRAD acceptance.
A16: Temporal screening (mode-dependent) | B16: Aviation scenarios use incidents on or after September 11, 2001. Pre-2001 aviation events are excluded unless a mechanism-based justification is recorded (the mechanism must be unaffected by ATSA, hardened flight deck doors, federalized screening). All other modes may use pre-2001 incidents, but only to establish a steady-state baseline. Pre-2001 non-aviation evidence must never be pooled or compared in aggregate against aviation estimates.
A17: Evidence beyond terrorist incidents | B17: The evidence base is deliberately broader than terrorism. Accidents with comparable physical mechanisms (e.g., accidental derailment for intentional derailment) inform first- AND second-order consequences. Crime and other serious security incidents inform first-order consequences ONLY. Outage, maintenance, and non-adversarial disruption events inform second-order/indirect consequences ONLY. Non-adversarial evidence never establishes adversary intent, capability, or attack frequency.
A18: Wiring status (v1.3) | B18: The v1.1/v1.2 methods are now live in the calculations, not just documented. Injury value pulls the weapon-class blended fraction via the Weapon Class column on Outcome Scenarios (column AE, dropdown-selectable). Second-order consequence uses EFFECTIVE outage days (engineering + regulatory delay), not engineering days. The Consequence Targets grid is 45 rows (5 targets x 9 durations, now including 45 and 90 days). Prior per-scenario fractions are archived in columns AF-AH for audit. Executive Summary target references use SUMIFS on target+duration so future grid changes cannot silently misalign them.
A19: MAIS injury traceability | B19: Every MAIS level (1-6) maps to a historical TSSRA bucket: MAIS 1-2 = minor injury, MAIS 3-5 = severe injury, MAIS 6 = death. Minor and severe use distinct VSL fractions. MAIS 6 fatalities are valued through the deaths line only, never the blended injury value, so no fatality is double counted. See VSL and Injuries sheet, mapping and validation blocks.
A20: Hijacking scenario splits | B20: Passenger and cargo hijacking are each split into a traditional variant (coercion/diversion; aircraft lands) and an aircraft-as-weapon variant (9/11-style ground-target impact). Lumping these masked the catastrophic tail. AV-05a/AV-06a are traditional; AV-05b/AV-06b are aircraft-as-weapon. The aircraft-as-weapon variants use 9/11 only for the ground-impact consequence mechanism, with the temporal-screen exception recorded per scenario.
A21: Probability and severity (scope note) | B21: Weapon-class severity mixes are conditional injury distributions given an event of that mechanism. They are NOT weighted by probability of occurrence. Consequence and frequency remain separated by design; probability is a later Bayesian phase and is not folded into the blended VSL.
A22: Dollar basis (2026) | B22: Property damage and second-order/economic losses are escalated to 2026 dollars using a documented CPI-U factor (12 months ending June 2026, +3.5%, BLS), held in an editable cell on the VSL and Injuries sheet (K6). The DOT value of a statistical life keeps its official 2025 basis and is clearly labeled; escalating a statutory agency value would misrepresent it. Nominal 2025 property inputs are archived alongside the escalated values.
A23: Cross-sector impacts view | B23: A dedicated Cross-Sector Impacts sheet monetizes the CISA-sector allocation of each target second-order loss (30-day, P50, 2026 dollars), presented separately so it can be read apart from the direct-cost results. These are static screening allocations pending CGE/REMI replacement and are not additive to direct-cost totals.

Sheet VSL and Injuries
A1: DOT Valuation of Statistical Life and Injury Severity
A3: Input | B3: Value | J3: Inflation Adjustment (property and economic inputs only)
A4: VSL (2025 dollars) | B4: 14200000 | J4: Input dollar basis | K4: 2025
A5: Guidance base year | B5: 2025 | J5: Target dollar basis | K5: 2026
A6: Source URL | B6: https://www.transportation.gov/office-policy/transportation-policy/revised-departmental-guidance-on-valuation-of-a-statistical-life-in-economic-analysis | J6: CPI-U 12-month factor | K6: 1.035
J7: Basis note | K7: CPI-U all items, 12 months ending June 2026 = +3.5% (BLS). Interim factor; update to the finalized 2026 annual average when published.
A8: MAIS | B8: Severity | C8: Fraction of VSL | D8: Dollar Value | F8: Note | J8: Source | K8: U.S. BLS, CPI-U, news.release/cpi.nr0.htm (June 2026, USDL-26-1191)
A9: MAIS 1 | B9: Minor | C9: 0.003 | D9: 42600 | F9: The single averaged MAIS fraction is deprecated. Injury cost is now built from an explicit severity MIX that differs by weapon class (see below). Blast mechanisms load the high-severity tail (MAIS 4-6) that a single average understates. | J9: Applies to | K9: Property damage and second-order/economic loss inputs. NOT applied to the DOT VSL, which remains at its official 2025 value.
A10: MAIS 2 | B10: Moderate | C10: 0.047 | D10: 667400
A11: MAIS 3 | B11: Serious | C11: 0.105 | D11: 1491000 | J11: Factor cell reference | K11: 'VSL and Injuries'!$K$6
A12: MAIS 4 | B12: Severe | C12: 0.266 | D12: 3777200
A13: MAIS 5 | B13: Critical | C13: 0.593 | D13: 8420600
A14: MAIS 6 | B14: Fatal/unsurvivable | C14: 1 | D14: 14200000
A18: Weapon-Class Severity Mix (bi-modal; replaces single averaged fraction)
A20: Weapon Class | B20: MAIS1 | C20: MAIS2 | D20: MAIS3 | E20: MAIS4 | F20: MAIS5 | G20: Blended Fraction | H20: Trauma Scoring Basis | J20: Row Share Check
A21: Blunt / vehicular (MAIS-adequate) | B21: 0.55 | C21: 0.28 | D21: 0.12 | E21: 0.04 | F21: 0.01 | G21: =B21*$C$9+C21*$C$10+D21*$C$11+E21*$C$12+F21*$C$13 -> 0.04398 | H21: MAIS/AIS; blunt trauma well-characterized | J21: =SUM(B21:F21) -> 1
A22: Ballistic / edged | B22: 0.3 | C22: 0.3 | D22: 0.22 | E22: 0.13 | F22: 0.05 | G22: =B22*$C$9+C22*$C$10+D22*$C$11+E22*$C$12+F22*$C$13 -> 0.10233 | H22: MAIS/AIS with penetrating-trauma tail | J22: =SUM(B22:F22) -> 1
A23: Blast (primary/secondary/quaternary) | B23: 0.2 | C23: 0.22 | D23: 0.25 | E23: 0.22 | F23: 0.11 | G23: =B23*$C$9+C23*$C$10+D23*$C$11+E23*$C$12+F23*$C$13 -> 0.16094 | H23: NISS + TRISS; multi-region blast injury | J23: =SUM(B23:F23) -> 1
A24: Chemical / biological | B24: 0.25 | C24: 0.25 | D24: 0.25 | E24: 0.17 | F24: 0.08 | G24: =B24*$C$9+C24*$C$10+D24*$C$11+E24*$C$12+F24*$C$13 -> 0.13141 | H24: Toxidrome severity; delayed-effect uncertainty | J24: =SUM(B24:F24) -> 1
A25: Share check (each row must equal 100%)
A26: Use: assign each scenario a weapon class; injury value = injuries x VSL x that class blended fraction. For blast-dominant scenarios do not use a single blended civilian-crash average.
A28: MAIS-to-TSSRA Bucket Mapping (injury traceability)
A29: Every MAIS severity level maps to exactly one historical TSSRA bucket. Fatalities (MAIS 6) are valued through the deaths line, NOT the blended injury value, so no fatality is double counted. Minor and severe injury buckets use distinct VSL fractions.
A31: MAIS Level | B31: Severity | C31: TSSRA Bucket | D31: VSL Fraction | E31: 2025 Dollar Value | F31: Valued Through
A32: MAIS 1 | B32: Minor | C32: Minor injury | D32: 0.003 | E32: =C9*$B$4 -> 42600 | F32: Blended injury value
A33: MAIS 2 | B33: Moderate | C33: Minor injury | D33: 0.047 | E33: =C10*$B$4 -> 667400 | F33: Blended injury value
A34: MAIS 3 | B34: Serious | C34: Severe injury | D34: 0.105 | E34: =C11*$B$4 -> 1491000 | F34: Blended injury value
A35: MAIS 4 | B35: Severe | C35: Severe injury | D35: 0.266 | E35: =C12*$B$4 -> 3777200 | F35: Blended injury value
A36: MAIS 5 | B36: Critical | C36: Severe injury | D36: 0.593 | E36: =C13*$B$4 -> 8420600 | F36: Blended injury value
A37: MAIS 6 | B37: Fatal/unsurvivable | C37: Death (fatality) | D37: 1 | E37: =C14*$B$4 -> 14200000 | F37: Deaths line (VSL x fatalities) - separate from injury value
A39: TSSRA Bucket Definitions
A40: Bucket | B40: MAIS Range | C40: Definition
A41: Minor injury | B41: MAIS 1-2 | C41: Treated and released or short recovery; no lasting impairment
A42: Severe injury | B42: MAIS 3-5 | C42: Hospitalization, potential permanent impairment, high acute-care cost
A43: Death (fatality) | B43: MAIS 6 | C43: Valued at full VSL through the deaths estimate, never through the injury blend
A46: Weapon-Class Injury Value, Split by Severe vs Minor Bucket (per injured person)
A47: Shows how each weapon class blended fraction decomposes into minor (MAIS 1-2) and severe (MAIS 3-5) buckets. Minor share x its VSL fractions + severe share x its VSL fractions = the blended fraction in the mix table above. Makes the severe/minor split explicit and auditable.
A49: Weapon Class | B49: Minor Share (MAIS1-2) | C49: Severe Share (MAIS3-5) | D49: Minor $ per injured | E49: Severe $ per injured | F49: Blended $ per injured | G49: Check vs mix table
A50: Blunt / vehicular (MAIS-adequate) | B50: =B21+C21 -> 0.83 | C50: =D21+E21+F21 -> 0.17 | D50: =(B21*$C$9+C21*$C$10)*$B$4 -> 210302 | E50: =(D21*$C$11+E21*$C$12+F21*$C$13)*$B$4 -> 414214 | F50: =D50+E50 -> 624516 | G50: =ROUND(F50/$B$4-G21,6) -> 0
A51: Ballistic / edged | B51: =B22+C22 -> 0.6 | C51: =D22+E22+F22 -> 0.4 | D51: =(B22*$C$9+C22*$C$10)*$B$4 -> 213000 | E51: =(D22*$C$11+E22*$C$12+F22*$C$13)*$B$4 -> 1240086 | F51: =D51+E51 -> 1453086 | G51: =ROUND(F51/$B$4-G22,6) -> 0
...

Sheet Evidence Screening
A1: Evidence Screening Rules (temporal + evidence class)
A2: Governs which incidents may enter the evidence base and what each may be used for. Applies to every scenario and every consequence target.
A4: 1. Temporal screening by mode
A5: Mode | B5: Period Screen | C5: Permitted Use | D5: Exception Rule | E5: Aggregation Rule
A6: Aviation (AV-01 to AV-11) | B6: On or after September 11, 2001 | C6: Full use for outcome and consequence estimation | D6: Pre-2001 aviation incident admissible ONLY with recorded mechanism-based justification: the mechanism must be unaffected by ATSA, hardened/locked flight deck doors, federalized screening, or expanded in-flight security | E6: Compare only against evidence screened to the same period
A7: Surface, pipeline, all other modes | B7: Pre-2001 admissible | C7: Steady-state baseline ONLY (long-run rates, severity distributions, physical-mechanism behavior) | D7: No exception needed; regime did not undergo an equivalent discontinuity | E7: MUST NOT be pooled or compared in aggregate against aviation estimates
A9: 2. Non-adversarial evidence classes and permitted scope
A10: Evidence Class | B10: Example | C10: Permitted Scope | D10: Prohibited Use
A11: Terrorist / intentional attack | B11: Vehicle ramming, aircraft hijacking | C11: First-order AND second-order consequences; adversary behavior | D11: None (primary evidence)
A12: Accident with comparable physical mechanism | B12: Accidental derailment as analog for intentional derailment; rupture, fire, collision, toxic release | C12: First-order AND second-order consequences; physical outcome, damage, restoration behavior | D12: Does not establish adversary intent, capability, target selection, or attack frequency
A13: Crime / other security-related serious incident | B13: Non-terrorist shooting or assault at a comparable target type | C13: First-order consequences ONLY (casualty counts, injury-severity mixes) | D13: Not used for indirect or cross-sector economic effects; not used for frequency
A14: Outage / maintenance / non-adversarial disruption | B14: Planned or unplanned service interruption, curtailment | C14: Second-order / indirect consequences ONLY (daily service-loss value, substitution, buffering, restoration curves) | D14: Not used to estimate casualties; not used for adversary behavior or frequency
A15: Mechanistic model | B15: Dispersion or crowd-exposure modeling where observations are absent | C15: Used where no observation exists; requires broad uncertainty and low confidence | D15: Does not raise confidence
A17: Per-run requirement | B17: Curate the referenced incident list each run: remove aviation incidents predating 2001-09-11 without recorded justification, confirm every reference is scenario-appropriate, verify no pre-2001 non-aviation evidence has been pooled into a cross-modal aggregate, and confirm each non-adversarial analog stays within its permitted scope.

Sheet Outcome Scenarios
A1: Conditional Outcome Estimates - All 9.0 Families
A3: ID | B3: Mode | C3: Scenario | D3: Evidence Class | E3: Confidence | F3: Primary Evidence / Analogs | G3: Low Fatalities | H3: Low Injuries | I3: Low Injury VSL Fraction | J3: Low Property Damage (2026$) | K3: Low Casualty Value | L3: Low Total Direct | M3: Best Fatalities | N3: Best Injuries | O3: Best Injury VSL Fraction | P3: Best Property Damage (2026$) | Q3: Best Casualty Value | R3: Best Total Direct | S3: High Fatalities | T3: High Injuries | U3: High Injury VSL Fraction | V3: High Property Damage (2026$) | W3: High Casualty Value | X3: High Total Direct | Y3: Source IDs | Z3: Key Assumptions | AA3: Limitations | AB3: Temporal Screen Applied | AC3: Pre-2001 Exception Justification (aviation only) | AD3: Non-Adversarial Evidence Used (class + permitted scope) | AE3: Weapon Class (drives injury severity mix) | AF3: Archived v1.2 Low Fraction | AG3: Archived v1.2 Best Fraction | AH3: Archived v1.2 High Fraction | AI3: Property Damage (nominal 2025) - Low | AJ3: Property Damage (nominal 2025) - Best | AK3: Property Damage (nominal 2025) - High
A4: AV-01 | B4: Aviation | C4: All UAS against aviation | D4: Mechanistic + observed disruption analogs | E4: Low | F4: FAA/GAO airport UAS sightings; TSA/CISA UAS threat guidance | G4: 0 | H4: 2 | I4: =IFERROR(INDEX('VSL and Injuries'!$G$21:$G$24,MATCH($AE4,'VSL and Injuries'!$A$21:$A$24,0)),"") -> 0.16094 | J4: =AI4*'VSL and Injuries'!$K$6 -> 517500 | K4: =G4*'VSL and Injuries'!$B$4+H4*'VSL and Injuries'!$B$4*I4 -> 4570696 | L4: =J4+K4 -> 5088196 | M4: 1 | N4: 15 | O4: =IFERROR(INDEX('VSL and Injuries'!$G$21:$G$24,MATCH($AE4,'VSL and Injuries'!$A$21:$A$24,0)),"") -> 0.16094 | P4: =AJ4*'VSL and Injuries'!$K$6 -> 10350000 | Q4: =M4*'VSL and Injuries'!$B$4+N4*'VSL and Injuries'!$B$4*O4 -> 48480220 | R4: =P4+Q4 -> 58830220 | S4: 20 | T4: 100 | U4: =IFERROR(INDEX('VSL and Injuries'!$G$21:$G$24,MATCH($AE4,'VSL and Injuries'!$A$21:$A$24,0)),"") -> 0.16094 | V4: =AK4*'VSL and Injuries'!$K$6 -> 155250000 | W4: =S4*'VSL and Injuries'!$B$4+T4*'VSL and Injuries'!$B$4*U4 -> 512534800 | X4: =V4+W4 -> 667784800 | Y4: S011; S012; S013 | Z4: Small-to-medium UAS event; ranges span disruption/collision through payload-enabled mass-casualty case; no active-war-zone incidents used. | AA4: No directly comparable successful domestic aviation UAS terrorist attack; high estimate is model-derived. | AB4: On or after 2001-09-11 (ATSA regime change) | AC4: None taken | AD4: To be recorded per run: accident (1st+2nd order) / crime (1st order only) / outage (2nd order only) | AE4: Blast (primary/secondary/quaternary) | AF4: 0.02 | AG4: 0.04 | AH4: 0.08 | AI4: 500000 | AJ4: 10000000 | AK4: 150000000
A5: AV-02 | B5: Aviation | C5: Aircraft assault on ground | D5: Observed attack analog + active-shooter analogs | E5: Moderate-Low | F5: Pan Am Flight 73 ground boarding attack; airport/transport active-shooter cases | G5: 0 | H5: 3 | I5: =IFERROR(INDEX('VSL and Injuries'!$G$21:$G$24,MATCH($AE5,'VSL and Injuries'!$A$21:$A$24,0)),"") -> 0.10233 | J5: =AI5*'VSL and Injuries'!$K$6 -> 1035000 | K5: =G5*'VSL and Injuries'!$B$4+H5*'VSL and Injuries'!$B$4*I5 -> 4359258 | L5: =J5+K5 -> 5394258 | M5: 8 | N5: 25 | O5: =IFERROR(INDEX('VSL and Injuries'!$G$21:$G$24,MATCH($AE5,'VSL and Injuries'!$A$21:$A$24,0)),"") -> 0.10233 | P5: =AJ5*'VSL and Injuries'!$K$6 -> 20700000 | Q5: =M5*'VSL and Injuries'!$B$4+N5*'VSL and Injuries'!$B$4*O5 -> 149927150 | R5: =P5+Q5 -> 170627150 | S5: 40 | T5: 100 | U5: =IFERROR(INDEX('VSL and Injuries'!$G$21:$G$24,MATCH($AE5,'VSL and Injuries'!$A$21:$A$24,0)),"") -> 0.10233 | V5: =AK5*'VSL and Injuries'!$K$6 -> 103500000 | W5: =S5*'VSL and Injuries'!$B$4+T5*'VSL and Injuries'!$B$4*U5 -> 713308600 | X5: =V5+W5 -> 816808600 | Y5: S006; S007; S023 | Z5: Occupied passenger aircraft at gate or stand; attacker access and response time drive dispersion. | AA5: Primary analog occurred outside the United States; aircraft and security configurations vary. | AB5: On or after 2001-09-11 (ATSA regime change) | AC5: None taken | AD5: To be recorded per run: accident (1st+2nd order) / crime (1st order only) / outage (2nd order only) | AE5: Ballistic / edged | AF5: 0.025 | AG5: 0.05 | AH5: 0.1 | AI5: 1000000 | AJ5: 20000000 | AK5: 100000000
A6: AV-03 | B6: Aviation | C6: Aircraft passenger assault with bladed weapons | D6: Observed attack/attempt analogs | E6: Moderate | F6: 9/11 Commission documentation; federal aircraft-interference and hijacking cases | G6: 0 | H6: 2 | I6: =IFERROR(INDEX('VSL and Injuries'!$G$21:$G$24,MATCH($AE6,'VSL and Injuries'!$A$21:$A$24,0)),"") -> 0.10233 | J6: =AI6*'VSL and Injuries'!$K$6 -> 103500 | K6: =G6*'VSL and Injuries'!$B$4+H6*'VSL and Injuries'!$B$4*I6 -> 2906172 | L6: =J6+K6 -> 3009672 | M6: 2 | N6: 8 | O6: =IFERROR(INDEX('VSL and Injuries'!$G$21:$G$24,MATCH($AE6,'VSL and Injuries'!$A$21:$A$24,0)),"") -> 0.10233 | P6: =AJ6*'VSL and Injuries'!$K$6 -> 517500 | Q6: =M6*'VSL and Injuries'!$B$4+N6*'VSL and Injuries'!$B$4*O6 -> 40024688 | R6: =P6+Q6 -> 40542188 | S6: 15 | T6: 35 | U6: =IFERROR(INDEX('VSL and Injuries'!$G$21:$G$24,MATCH($AE6,'VSL and Injuries'!$A$21:$A$24,0)),"") -> 0.10233 | V6: =AK6*'VSL and Injuries'!$K$6 -> 5175000 | W6: =S6*'VSL and Injuries'!$B$4+T6*'VSL and Injuries'!$B$4*U6 -> 263858010 | X6: =V6+W6 -> 269033010 | Y6: S005; S022 | Z6: Close-quarters assault without successful use of aircraft as a weapon; intervention and cockpit security remain active mitigations. | AA6: Small sample and major post-2001 security regime change. | AB6: On or after 2001-09-11 (ATSA regime change) | AC6: None taken | AD6: To be recorded per run: accident (1st+2nd order) / crime (1st order only) / outage (2nd order only) | AE6: Ballistic / edged | AF6: 0.02 | AG6: 0.035 | AH6: 0.08 | AI6: 100000 | AJ6: 500000 | AK6: 5000000
A7: AV-04 | B7: Aviation | C7: Airport passenger assembly assault | D7: Observed domestic airport + public assembly analogs | E7: Moderate | F7: Fort Lauderdale airport shooting; FBI active-shooter series | G7: 2 | H7: 8 | I7: =IFERROR(INDEX('VSL and Injuries'!$G$21:$G$24,MATCH($AE7,'VSL and Injuries'!$A$21:$A$24,0)),"") -> 0.10233 | J7: =AI7*'VSL and Injuries'!$K$6 -> 517500 | K7: =G7*'VSL and Injuries'!$B$4+H7*'VSL and Injuries'!$B$4*I7 -> 40024688 | L7: =J7+K7 -> 40542188 | M7: 10 | N7: 45 | O7: =IFERROR(INDEX('VSL and Injuries'!$G$21:$G$24,MATCH($AE7,'VSL and Injuries'!$A$21:$A$24,0)),"") -> 0.10233 | P7: =AJ7*'VSL and Injuries'!$K$6 -> 5175000 | Q7: =M7*'VSL and Injuries'!$B$4+N7*'VSL and Injuries'!$B$4*O7 -> 207388870 | R7: =P7+Q7 -> 212563870 | S7: 50 | T7: 200 | U7: =IFERROR(INDEX('VSL and Injuries'!$G$21:$G$24,MATCH($AE7,'VSL and Injuries'!$A$21:$A$24,0)),"") -> 0.10233 | V7: =AK7*'VSL and Injuries'!$K$6 -> 51750000 | W7: =S7*'VSL and Injuries'!$B$4+T7*'VSL and Injuries'!$B$4*U7 -> 1000617200 | X7: =V7+W7 -> 1052367200 | Y7: S007; S023 | Z7: Public-side or baggage-claim passenger assembly; no explosive effects included. | AA7: Casualties depend heavily on crowd density, weapon, duration, and police response. | AB7: On or after 2001-09-11 (ATSA regime change) | AC7: None taken | AD7: To be recorded per run: accident (1st+2nd order) / crime (1st order only) / outage (2nd order only) | AE7: Ballistic / edged | AF7: 0.025 | AG7: 0.05 | AH7: 0.1 | AI7: 500000 | AJ7: 5000000 | AK7: 50000000
A8: AV-05a | B8: Aviation | C8: Commercial passenger aircraft hijacking - traditional (coercion or diversion; aircraft lands) | D8: Attempt or advanced plot | E8: Moderate-Low | F8: Post-2001 aviation hijacking attempts and thwarted takeovers; onboard assault cases | G8: 0 | H8: 3 | I8: =IFERROR(INDEX('VSL and Injuries'!$G$21:$G$24,MATCH($AE8,'VSL and Injuries'!$A$21:$A$24,0)),"") -> 0.10233 | J8: =AI8*'VSL and Injuries'!$K$6 -> 2070000 | K8: =G8*'VSL and Injuries'!$B$4+H8*'VSL and Injuries'!$B$4*I8 -> 4359258 | L8: =K8+J8 -> 6429258 | M8: 2 | N8: 15 | O8: =IFERROR(INDEX('VSL and Injuries'!$G$21:$G$24,MATCH($AE8,'VSL and Injuries'!$A$21:$A$24,0)),"") -> 0.10233 | P8: =AJ8*'VSL and Injuries'!$K$6 -> 20700000 | Q8: =M8*'VSL and Injuries'!$B$4+N8*'VSL and Injuries'!$B$4*O8 -> 50196290 | R8: =Q8+P8 -> 70896290 | S8: 12 | T8: 60 | U8: =IFERROR(INDEX('VSL and Injuries'!$G$21:$G$24,MATCH($AE8,'VSL and Injuries'!$A$21:$A$24,0)),"") -> 0.10233 | V8: =AK8*'VSL and Injuries'!$K$6 -> 155250000 | W8: =S8*'VSL and Injuries'!$B$4+T8*'VSL and Injuries'!$B$4*U8 -> 257585160 | X8: =W8+V8 -> 412835160 | Y8: S007; S019; S032; S033 | Z8: Objective is coercion, diversion, or hostage leverage. Hardened cockpit doors and passenger response make cockpit breach and aircraft-as-weapon use unlikely. Casualties bounded by onboard population and standoff violence; property primarily airframe and ground handling. | AA8: Post-2001 successful U.S. passenger takeovers are near-absent; estimates rely on attempts, foreign analogs screened to post-2001, and onboard-assault mechanisms. | AB8: On or after 2001-09-11 (ATSA regime change) | AC8: None taken | AD8: Onboard-assault accident analogs used for casualty severity only (1st order); not for adversary capability. | AE8: Ballistic / edged | AF8: 0.025 | AG8: 0.06 | AH8: 0.12 | AI8: 2000000 | AJ8: 20000000 | AK8: 150000000
A9: AV-06a | B9: Aviation | C9: Cargo aircraft hijacking - traditional (diversion or theft; aircraft lands) | D9: Attempt or advanced plot | E9: Low | F9: Cargo aircraft security incidents; ground-based cargo theft and diversion analogs | G9: 0 | H9: 1 | I9: =IFERROR(INDEX('VSL and Injuries'!$G$21:$G$24,MATCH($AE9,'VSL and Injuries'!$A$21:$A$24,0)),"") -> 0.10233 | J9: =AI9*'VSL and Injuries'!$K$6 -> 5175000 | K9: =G9*'VSL and Injuries'!$B$4+H9*'VSL and Injuries'!$B$4*I9 -> 1453086 | L9: =K9+J9 -> 6628086 | M9: 1 | N9: 4 | O9: =IFERROR(INDEX('VSL and Injuries'!$G$21:$G$24,MATCH($AE9,'VSL and Injuries'!$A$21:$A$24,0)),"") -> 0.10233 | P9: =AJ9*'VSL and Injuries'!$K$6 -> 25875000 | Q9: =M9*'VSL and Injuries'!$B$4+N9*'VSL and Injuries'!$B$4*O9 -> 20012344 | R9: =Q9+P9 -> 45887344 | S9: 6 | T9: 15 | U9: =IFERROR(INDEX('VSL and Injuries'!$G$21:$G$24,MATCH($AE9,'VSL and Injuries'!$A$21:$A$24,0)),"") -> 0.10233 | V9: =AK9*'VSL and Injuries'!$K$6 -> 124200000 | W9: =S9*'VSL and Injuries'!$B$4+T9*'VSL and Injuries'!$B$4*U9 -> 106996290 | X9: =W9+V9 -> 231196290 | Y9: S017; S018; S029 | Z9: Objective is theft, diversion, or ground use; minimal onboard population (crew only). Consequence dominated by airframe value and cargo loss, not mass casualty. | AA9: Very sparse direct evidence; small cargo crews cap casualty ceilings; relies on cargo-security and diversion analogs. | AB9: On or after 2001-09-11 (ATSA regime change) | AC9: None taken | AD9: Cargo-theft and diversion accident analogs used for property/business estimates only (1st and 2nd order). | AE9: Ballistic / edged | AF9: 0.02 | AG9: 0.05 | AH9: 0.1 | AI9: 5000000 | AJ9: 25000000 | AK9: 120000000
A10: AV-07 | B10: Aviation | C10: Public charter hijacking | D10: Commercial hijacking analog with smaller occupancy | E10: Low | F10: Commercial hijacking record adjusted for charter occupancy and security variability | G10: 0 | H10: 2 | I10: =IFERROR(INDEX('VSL and Injuries'!$G$21:$G$24,MATCH($AE10,'VSL and Injuries'!$A$21:$A$24,0)),"") -> 0.10233 | J10: =AI10*'VSL and Injuries'!$K$6 -> 2070000 | K10: =G10*'VSL and Injuries'!$B$4+H10*'VSL and Injuries'!$B$4*I10 -> 2906172 | L10: =J10+K10 -> 4976172 | M10: 10 | N10: 25 | O10: =IFERROR(INDEX('VSL and Injuries'!$G$21:$G$24,MATCH($AE10,'VSL and Injuries'!$A$21:$A$24,0)),"") -> 0.10233 | P10: =AJ10*'VSL and Injuries'!$K$6 -> 31050000 | Q10: =M10*'VSL and Injuries'!$B$4+N10*'VSL and Injuries'!$B$4*O10 -> 178327150 | R10: =P10+Q10 -> 209377150 | S10: 100 | T10: 125 | U10: =IFERROR(INDEX('VSL and Injuries'!$G$21:$G$24,MATCH($AE10,'VSL and Injuries'!$A$21:$A$24,0)),"") -> 0.10233 | V10: =AK10*'VSL and Injuries'!$K$6 -> 207000000 | W10: =S10*'VSL and Injuries'!$B$4+T10*'VSL and Injuries'!$B$4*U10 -> 1601635750 | X10: =V10+W10 -> 1808635750 | Y10: S005; S006; S019 | Z10: Passenger charter aircraft; occupancy and screening controls may differ from scheduled service. | AA10: Public charter is heterogeneous; estimate must be tailored to aircraft and passenger count. | AB10: On or after 2001-09-11 (ATSA regime change) | AC10: None taken | AD10: To be recorded per run: accident (1st+2nd order) / crime (1st order only) / outage (2nd order only) | AE10: Ballistic / edged | AF10: 0.02 | AG10: 0.05 | AH10: 0.1 | AI10: 2000000 | AJ10: 30000000 | AK10: 200000000
A11: AV-08 | B11: Aviation | C11: All IID on commercial passenger aircraft | D11: Fire/sabotage analogs + evacuation studies | E11: Moderate-Low | F11: NTSB explosive/fire investigations and evacuation safety study | G11: 0 | H11: 5 | I11: =IFERROR(INDEX('VSL and Injuries'!$G$21:$G$24,MATCH($AE11,'VSL and Injuries'!$A$21:$A$24,0)),"") -> 0.16094 | J11: =AI11*'VSL and Injuries'!$K$6 -> 1035000 | K11: =G11*'VSL and Injuries'!$B$4+H11*'VSL and Injuries'!$B$4*I11 -> 11426740 | L11: =J11+K11 -> 12461740 | M11: 8 | N11: 40 | O11: =IFERROR(INDEX('VSL and Injuries'!$G$21:$G$24,MATCH($AE11,'VSL and Injuries'!$A$21:$A$24,0)),"") -> 0.16094 | P11: =AJ11*'VSL and Injuries'!$K$6 -> 25875000 | Q11: =M11*'VSL and Injuries'!$B$4+N11*'VSL and Injuries'!$B$4*O11 -> 205013920 | R11: =P11+Q11 -> 230888920 | S11: 120 | T11: 180 | U11: =IFERROR(INDEX('VSL and Injuries'!$G$21:$G$24,MATCH($AE11,'VSL and Injuries'!$A$21:$A$24,0)),"") -> 0.16094 | V11: =AK11*'VSL and Injuries'!$K$6 -> 155250000 | W11: =S11*'VSL and Injuries'!$B$4+T11*'VSL and Injuries'!$B$4*U11 -> 2115362640 | X11: =V11+W11 -> 2270612640 | Y11: S004; S025 | Z11: IID interpreted as improvised incendiary device; outcomes span contained cabin fire to loss of aircraft. | AA11: Confirm IID definition before operational use; fire behavior varies by location and phase of flight. | AB11: On or after 2001-09-11 (ATSA regime change) | AC11: None taken | AD11: To be recorded per run: accident (1st+2nd order) / crime (1st order only) / outage (2nd order only) | AE11: Blast (primary/secondary/quaternary) | AF11: 0.03 | AG11: 0.08 | AH11: 0.15 | AI11: 1000000 | AJ11: 25000000 | AK11: 150000000
A12: AV-09 | B12: Aviation | C12: All IID on cargo aircraft | D12: Cargo-fire/sabotage analogs + mechanistic model | E12: Low | F12: NTSB fire/explosion reports and cargo-aircraft economic values | G12: 0 | H12: 1 | I12: =IFERROR(INDEX('VSL and Injuries'!$G$21:$G$24,MATCH($AE12,'VSL and Injuries'!$A$21:$A$24,0)),"") -> 0.16094 | J12: =AI12*'VSL and Injuries'!$K$6 -> 5175000 | K12: =G12*'VSL and Injuries'!$B$4+H12*'VSL and Injuries'!$B$4*I12 -> 2285348 | L12: =J12+K12 -> 7460348 | M12: 2 | N12: 8 | O12: =IFERROR(INDEX('VSL and Injuries'!$G$21:$G$24,MATCH($AE12,'VSL and Injuries'!$A$21:$A$24,0)),"") -> 0.16094 | P12: =AJ12*'VSL and Injuries'!$K$6 -> 36225000 | Q12: =M12*'VSL and Injuries'!$B$4+N12*'VSL and Injuries'!$B$4*O12 -> 46682784 | R12: =P12+Q12 -> 82907784 | S12: 25 | T12: 50 | U12: =IFERROR(INDEX('VSL and Injuries'!$G$21:$G$24,MATCH($AE12,'VSL and Injuries'!$A$21:$A$24,0)),"") -> 0.16094 | V12: =AK12*'VSL and Injuries'!$K$6 -> 207000000 | W12: =S12*'VSL and Injuries'!$B$4+T12*'VSL and Injuries'!$B$4*U12 -> 469267400 | X12: =V12+W12 -> 676267400 | Y12: S004; S019; S025 | Z12: IID interpreted as improvised incendiary device; limited crew but potentially high aircraft/cargo loss. | AA12: Cargo type and fire-suppression capability materially alter outcomes. | AB12: On or after 2001-09-11 (ATSA regime change) | AC12: None taken | AD12: To be recorded per run: accident (1st+2nd order) / crime (1st order only) / outage (2nd order only) | AE12: Blast (primary/secondary/quaternary) | AF12: 0.025 | AG12: 0.07 | AH12: 0.14 | AI12: 5000000 | AJ12: 35000000 | AK12: 200000000
A13: AV-10 | B13: Aviation | C13: All Chem/Bio on commercial passenger aircraft | D13: Mechanistic toxicology model + mass-exposure guidance | E13: Low | F13: CDC chemical-agent health guidance; EPA dispersion tools; federal decontamination guidance | G13: 0 | H13: 10 | I13: =IFERROR(INDEX('VSL and Injuries'!$G$21:$G$24,MATCH($AE13,'VSL and Injuries'!$A$21:$A$24,0)),"") -> 0.13141 | J13: =AI13*'VSL and Injuries'!$K$6 -> 1035000 | K13: =G13*'VSL and Injuries'!$B$4+H13*'VSL and Injuries'!$B$4*I13 -> 18660220 | L13: =J13+K13 -> 19695220 | M13: 5 | N13: 100 | O13: =IFERROR(INDEX('VSL and Injuries'!$G$21:$G$24,MATCH($AE13,'VSL and Injuries'!$A$21:$A$24,0)),"") -> 0.13141 | P13: =AJ13*'VSL and Injuries'!$K$6 -> 10350000 | Q13: =M13*'VSL and Injuries'!$B$4+N13*'VSL and Injuries'!$B$4*O13 -> 257602200 | R13: =P13+Q13 -> 267952200 | S13: 75 | T13: 300 | U13: =IFERROR(INDEX('VSL and Injuries'!$G$21:$G$24,MATCH($AE13,'VSL and Injuries'!$A$21:$A$24,0)),"") -> 0.13141 | V13: =AK13*'VSL and Injuries'!$K$6 -> 77625000 | W13: =S13*'VSL and Injuries'!$B$4+T13*'VSL and Injuries'!$B$4*U13 -> 1624806600 | X13: =V13+W13 -> 1702431600 | Y13: S015; S016; S026 | Z13: Generic toxic chemical or biological exposure; excludes agent-specific classified parameters. | AA13: Agent, dose, ventilation, detection, medical response, and incubation dominate results. | AB13: On or after 2001-09-11 (ATSA regime change) | AC13: None taken | AD13: To be recorded per run: accident (1st+2nd order) / crime (1st order only) / outage (2nd order only) | AE13: Chemical / biological | AF13: 0.03 | AG13: 0.08 | AH13: 0.18 | AI13: 1000000 | AJ13: 10000000 | AK13: 75000000
A14: AV-11 | B14: Aviation | C14: All Chem/Bio at airport | D14: Mechanistic dispersion + public-space mass-exposure analogs | E14: Low | F14: CDC toxicology; EPA ALOHA/CAMEO; public mass-decontamination guidance | G14: 0 | H14: 25 | I14: =IFERROR(INDEX('VSL and Injuries'!$G$21:$G$24,MATCH($AE14,'VSL and Injuries'!$A$21:$A$24,0)),"") -> 0.13141 | J14: =AI14*'VSL and Injuries'!$K$6 -> 2070000 | K14: =G14*'VSL and Injuries'!$B$4+H14*'VSL and Injuries'!$B$4*I14 -> 46650550 | L14: =J14+K14 -> 48720550 | M14: 15 | N14: 300 | O14: =IFERROR(INDEX('VSL and Injuries'!$G$21:$G$24,MATCH($AE14,'VSL and Injuries'!$A$21:$A$24,0)),"") -> 0.13141 | P14: =AJ14*'VSL and Injuries'!$K$6 -> 31050000 | Q14: =M14*'VSL and Injuries'!$B$4+N14*'VSL and Injuries'!$B$4*O14 -> 772806600 | R14: =P14+Q14 -> 803856600 | S14: 150 | T14: 1500 | U14: =IFERROR(INDEX('VSL and Injuries'!$G$21:$G$24,MATCH($AE14,'VSL and Injuries'!$A$21:$A$24,0)),"") -> 0.13141 | V14: =AK14*'VSL and Injuries'!$K$6 -> 258750000 | W14: =S14*'VSL and Injuries'!$B$4+T14*'VSL and Injuries'!$B$4*U14 -> 4929033000 | X14: =V14+W14 -> 5187783000 | Y14: S015; S016; S026 | Z14: Public terminal release with variable ventilation and rapid emergency response. | AA14: Not agent-specific; high case is an intentionally broad planning bound. | AB14: On or after 2001-09-11 (ATSA regime change) | AC14: None taken | AD14: To be recorded per run: accident (1st+2nd order) / crime (1st order only) / outage (2nd order only) | AE14: Chemical / biological | AF14: 0.025 | AG14: 0.07 | AH14: 0.16 | AI14: 2000000 | AJ14: 30000000 | AK14: 250000000
A15: SU-01 | B15: Surface | C15: Assault on surface passenger vessels/stations | D15: Observed transit shooting + active-shooter/European attack analogs | E15: Moderate | F15: Brooklyn subway mass shooting; FBI active-shooter record; Europol TE-SAT | G15: 1 | H15: 5 | I15: =IFERROR(INDEX('VSL and Injuries'!$G$21:$G$24,MATCH($AE15,'VSL and Injuries'!$A$21:$A$24,0)),"") -> 0.10233 | J15: =AI15*'VSL and Injuries'!$K$6 -> 517500 | K15: =G15*'VSL and Injuries'!$B$4+H15*'VSL and Injuries'!$B$4*I15 -> 21465430 | L15: =J15+K15 -> 21982930 | M15: 10 | N15: 50 | O15: =IFERROR(INDEX('VSL and Injuries'!$G$21:$G$24,MATCH($AE15,'VSL and Injuries'!$A$21:$A$24,0)),"") -> 0.10233 | P15: =AJ15*'VSL and Injuries'!$K$6 -> 5175000 | Q15: =M15*'VSL and Injuries'!$B$4+N15*'VSL and Injuries'!$B$4*O15 -> 214654300 | R15: =P15+Q15 -> 219829300 | S15: 60 | T15: 250 | U15: =IFERROR(INDEX('VSL and Injuries'!$G$21:$G$24,MATCH($AE15,'VSL and Injuries'!$A$21:$A$24,0)),"") -> 0.10233 | V15: =AK15*'VSL and Injuries'!$K$6 -> 51750000 | W15: =S15*'VSL and Injuries'!$B$4+T15*'VSL and Injuries'!$B$4*U15 -> 1215271500 | X15: =V15+W15 -> 1267021500 | Y15: S008; S021; S023 | Z15: Firearm/grenade or bladed assault at vessel, station, or vehicle; ranges combine distinct subtypes. | AA15: Scenario should eventually be separated by vessel, station, and onboard configuration. | AB15: Pre-2001 admissible; steady-state use only; not aggregated with aviation | AC15: n/a (non-aviation) | AD15: To be recorded per run: accident (1st+2nd order) / crime (1st order only) / outage (2nd order only) | AE15: Ballistic / edged | AF15: 0.025 | AG15: 0.05 | AH15: 0.11 | AI15: 500000 | AJ15: 5000000 | AK15: 50000000
A16: SU-02 | B16: Surface | C16: Assault on Pipeline ICS center | D16: Facility assault analog + pipeline control-system consequence evidence | E16: Low | F16: FBI active-shooter distributions; NTSB SCADA/control-system investigations; CISA critical infrastructure guidance | G16: 0 | H16: 2 | I16: =IFERROR(INDEX('VSL and Injuries'!$G$21:$G$24,MATCH($AE16,'VSL and Injuries'!$A$21:$A$24,0)),"") -> 0.10233 | J16: =AI16*'VSL and Injuries'!$K$6 -> 517500 | K16: =G16*'VSL and Injuries'!$B$4+H16*'VSL and Injuries'!$B$4*I16 -> 2906172 | L16: =J16+K16 -> 3423672 | M16: 2 | N16: 10 | O16: =IFERROR(INDEX('VSL and Injuries'!$G$21:$G$24,MATCH($AE16,'VSL and Injuries'!$A$21:$A$24,0)),"") -> 0.10233 | P16: =AJ16*'VSL and Injuries'!$K$6 -> 5175000 | Q16: =M16*'VSL and Injuries'!$B$4+N16*'VSL and Injuries'!$B$4*O16 -> 42930860 | R16: =P16+Q16 -> 48105860 | S16: 10 | T16: 40 | U16: =IFERROR(INDEX('VSL and Injuries'!$G$21:$G$24,MATCH($AE16,'VSL and Injuries'!$A$21:$A$24,0)),"") -> 0.10233 | V16: =AK16*'VSL and Injuries'!$K$6 -> 51750000 | W16: =S16*'VSL and Injuries'!$B$4+T16*'VSL and Injuries'!$B$4*U16 -> 200123440 | X16: =V16+W16 -> 251873440 | Y16: S003; S023; S030 | Z16: Direct casualties/property damage at control center only; pipeline service loss is modeled in the consequence module. | AA16: Public data on pipeline-control-center attacks are extremely limited. | AB16: Pre-2001 admissible; steady-state use only; not aggregated with aviation | AC16: n/a (non-aviation) | AD16: To be recorded per run: accident (1st+2nd order) / crime (1st order only) / outage (2nd order only) | AE16: Ballistic / edged | AF16: 0.02 | AG16: 0.04 | AH16: 0.08 | AI16: 500000 | AJ16: 5000000 | AK16: 50000000
A17: SU-03 | B17: Surface | C17: Vehicle ramming | D17: Observed domestic terrorist and extremist attacks | E17: Moderate-High | F17: New York 2017 truck attack; New Orleans 2025 attack; Charlottesville 2017 | G17: 1 | H17: 5 | I17: =IFERROR(INDEX('VSL and Injuries'!$G$21:$G$24,MATCH($AE17,'VSL and Injuries'!$A$21:$A$24,0)),"") -> 0.04398 | J17: =AI17*'VSL and Injuries'!$K$6 -> 103500 | K17: =G17*'VSL and Injuries'!$B$4+H17*'VSL and Injuries'!$B$4*I17 -> 17322580 | L17: =J17+K17 -> 17426080 | M17: 8 | N17: 35 | O17: =IFERROR(INDEX('VSL and Injuries'!$G$21:$G$24,MATCH($AE17,'VSL and Injuries'!$A$21:$A$24,0)),"") -> 0.04398 | P17: =AJ17*'VSL and Injuries'!$K$6 -> 1035000 | Q17: =M17*'VSL and Injuries'!$B$4+N17*'VSL and Injuries'!$B$4*O17 -> 135458060 | R17: =P17+Q17 -> 136493060 | S17: 40 | T17: 150 | U17: =IFERROR(INDEX('VSL and Injuries'!$G$21:$G$24,MATCH($AE17,'VSL and Injuries'!$A$21:$A$24,0)),"") -> 0.04398 | V17: =AK17*'VSL and Injuries'!$K$6 -> 10350000 | W17: =S17*'VSL and Injuries'!$B$4+T17*'VSL and Injuries'!$B$4*U17 -> 661677400 | X17: =V17+W17 -> 672027400 | Y17: S009; S010; S027 | Z17: Single vehicle against a dense pedestrian area; excludes secondary explosives/firearms unless part of observed casualty totals. | AA17: Vehicle mass, speed, barriers, crowd geometry, and follow-on actions strongly affect results. | AB17: Pre-2001 admissible; steady-state use only; not aggregated with aviation | AC17: n/a (non-aviation) | AD17: To be recorded per run: accident (1st+2nd order) / crime (1st order only) / outage (2nd order only) | AE17: Blunt / vehicular (MAIS-adequate) | AF17: 0.03 | AG17: 0.06 | AH17: 0.12 | AI17: 100000 | AJ17: 1000000 | AK17: 10000000
A18: SU-04 | B18: Surface | C18: All UAS against surface transportation | D18: Mechanistic + critical-infrastructure threat guidance | E18: Low | F18: CISA UAS critical-infrastructure guidance; TSA C-UAS program; GAO unauthorized UAS findings | G18: 0 | H18: 3 | I18: =IFERROR(INDEX('VSL and Injuries'!$G$21:$G$24,MATCH($AE18,'VSL and Injuries'!$A$21:$A$24,0)),"") -> 0.16094 | J18: =AI18*'VSL and Injuries'!$K$6 -> 258750 | K18: =G18*'VSL and Injuries'!$B$4+H18*'VSL and Injuries'!$B$4*I18 -> 6856044 | L18: =J18+K18 -> 7114794 | M18: 2 | N18: 20 | O18: =IFERROR(INDEX('VSL and Injuries'!$G$21:$G$24,MATCH($AE18,'VSL and Injuries'!$A$21:$A$24,0)),"") -> 0.16094 | P18: =AJ18*'VSL and Injuries'!$K$6 -> 5175000 | Q18: =M18*'VSL and Injuries'!$B$4+N18*'VSL and Injuries'!$B$4*O18 -> 74106960 | R18: =P18+Q18 -> 79281960 | S18: 20 | T18: 100 | U18: =IFERROR(INDEX('VSL and Injuries'!$G$21:$G$24,MATCH($AE18,'VSL and Injuries'!$A$21:$A$24,0)),"") -> 0.16094 | V18: =AK18*'VSL and Injuries'!$K$6 -> 51750000 | W18: =S18*'VSL and Injuries'!$B$4+T18*'VSL and Injuries'!$B$4*U18 -> 512534800 | X18: =V18+W18 -> 564284800 | Y18: S011; S012; S013 | Z18: Ranges cover surveillance/disruption, collision, and limited payload attack against surface systems. | AA18: No directly comparable successful domestic terrorist event; high estimate is model-derived. | AB18: Pre-2001 admissible; steady-state use only; not aggregated with aviation | AC18: n/a (non-aviation) | AD18: To be recorded per run: accident (1st+2nd order) / crime (1st order only) / outage (2nd order only) | AE18: Blast (primary/secondary/quaternary) | AF18: 0.02 | AG18: 0.05 | AH18: 0.1 | AI18: 250000 | AJ18: 5000000 | AK18: 50000000
A19: SU-05 | B19: Surface | C19: Chem/Bio contamination of food transported by tanker truck | D19: Food-defense vulnerability framework + mechanistic public-health model | E19: Low | F19: FDA intentional-adulteration rule and bulk-food transport guidance; CDC toxicology | G19: 0 | H19: 10 | I19: =IFERROR(INDEX('VSL and Injuries'!$G$21:$G$24,MATCH($AE19,'VSL and Injuries'!$A$21:$A$24,0)),"") -> 0.13141 | J19: =AI19*'VSL and Injuries'!$K$6 -> 517500 | K19: =G19*'VSL and Injuries'!$B$4+H19*'VSL and Injuries'!$B$4*I19 -> 18660220 | L19: =J19+K19 -> 19177720 | M19: 10 | N19: 250 | O19: =IFERROR(INDEX('VSL and Injuries'!$G$21:$G$24,MATCH($AE19,'VSL and Injuries'!$A$21:$A$24,0)),"") -> 0.13141 | P19: =AJ19*'VSL and Injuries'!$K$6 -> 15525000 | Q19: =M19*'VSL and Injuries'!$B$4+N19*'VSL and Injuries'!$B$4*O19 -> 608505500 | R19: =P19+Q19 -> 624030500 | S19: 250 | T19: 3000 | U19: =IFERROR(INDEX('VSL and Injuries'!$G$21:$G$24,MATCH($AE19,'VSL and Injuries'!$A$21:$A$24,0)),"") -> 0.13141 | V19: =AK19*'VSL and Injuries'!$K$6 -> 103500000 | W19: =S19*'VSL and Injuries'!$B$4+T19*'VSL and Injuries'!$B$4*U19 -> 9148066000 | X19: =V19+W19 -> 9251566000 | Y19: S014; S015; S028 | Z19: Contamination enters a distributed food stream before detection; recalls and business interruption are excluded from outcome property damage. | AA19: Highly sensitive to food type, dilution, dose, detection point, distribution reach, and treatment. | AB19: Pre-2001 admissible; steady-state use only; not aggregated with aviation | AC19: n/a (non-aviation) | AD19: To be recorded per run: accident (1st+2nd order) / crime (1st order only) / outage (2nd order only) | AE19: Chemical / biological | AF19: 0.015 | AG19: 0.04 | AH19: 0.1 | AI19: 500000 | AJ19: 15000000 | AK19: 100000000
A20: AV-05b | B20: Aviation | C20: Commercial passenger aircraft hijacking - aircraft as weapon into populated/economic target (9/11-style) | D20: Mechanistic model | E20: Low | F20: 9/11 Commission documentation for ground-target impact mechanism; structural-collapse and mass-casualty building-impact analogs | G20: 100 | H20: 150 | I20: =IFERROR(INDEX('VSL and Injuries'!$G$21:$G$24,MATCH($AE20,'VSL and Injuries'!$A$21:$A$24,0)),"") -> 0.16094 | J20: =AI20*'VSL and Injuries'!$K$6 -> 517500000 | K20: =G20*'VSL and Injuries'!$B$4+H20*'VSL and Injuries'!$B$4*I20 -> 1762802200 | L20: =K20+J20 -> 2280302200 | M20: 500 | N20: 800 | O20: =IFERROR(INDEX('VSL and Injuries'!$G$21:$G$24,MATCH($AE20,'VSL and Injuries'!$A$21:$A$24,0)),"") -> 0.16094 | P20: =AJ20*'VSL and Injuries'!$K$6 -> 5175000000 | Q20: =M20*'VSL and Injuries'!$B$4+N20*'VSL and Injuries'!$B$4*O20 -> 8928278400 | R20: =Q20+P20 -> 14103278400 | S20: 3000 | T20: 6000 | U20: =IFERROR(INDEX('VSL and Injuries'!$G$21:$G$24,MATCH($AE20,'VSL and Injuries'!$A$21:$A$24,0)),"") -> 0.16094 | V20: =AK20*'VSL and Injuries'!$K$6 -> 41400000000 | W20: =S20*'VSL and Injuries'!$B$4+T20*'VSL and Injuries'!$B$4*U20 -> 56312088000 | X20: =W20+V20 -> 97712088000 | Y20: S007; S019; S032; S033 | Z20: Objective is to use the aircraft as a weapon against a high-occupancy ground target. Casualties and property dominated by the ground target, not the aircraft; blast/structural-collapse trauma governs injury severity. This is the catastrophic tail previously buried inside the lumped hijacking family. | AA20: Single defining U.S. event (2001) predates the post-2001 screen; used ONLY for the ground-impact mechanism, which the 2001-2002 regime change does not alter given breach. Probability of success not modeled; conditional consequence only. | AB20: On or after 2001-09-11 (ATSA regime change) | AC20: Exception taken: 9/11 used for ground-impact CONSEQUENCE mechanism only. Hardened doors/ATSA screening reduce likelihood of breach but do not change the physical consequence conditional on aircraft-as-weapon use. Recorded per Section 4.4. | AD20: Building-collapse and mass-casualty structural analogs used for casualty/property scale (1st order) only; not for adversary capability or feasibility. | AE20: Blast (primary/secondary/quaternary) | AI20: 500000000 | AJ20: 5000000000 | AK20: 40000000000
A21: AV-06b | B21: Aviation | C21: Cargo aircraft hijacking - aircraft as weapon into populated/economic target | D21: Mechanistic model | E21: Low | F21: Aircraft-as-weapon ground-impact mechanism (as AV-05b), scaled to cargo airframe; no onboard passenger load | G21: 50 | H21: 80 | I21: =IFERROR(INDEX('VSL and Injuries'!$G$21:$G$24,MATCH($AE21,'VSL and Injuries'!$A$21:$A$24,0)),"") -> 0.16094 | J21: =AI21*'VSL and Injuries'!$K$6 -> 310500000 | K21: =G21*'VSL and Injuries'!$B$4+H21*'VSL and Injuries'!$B$4*I21 -> 892827840 | L21: =K21+J21 -> 1203327840 | M21: 300 | N21: 500 | O21: =IFERROR(INDEX('VSL and Injuries'!$G$21:$G$24,MATCH($AE21,'VSL and Injuries'!$A$21:$A$24,0)),"") -> 0.16094 | P21: =AJ21*'VSL and Injuries'!$K$6 -> 3105000000 | Q21: =M21*'VSL and Injuries'!$B$4+N21*'VSL and Injuries'!$B$4*O21 -> 5402674000 | R21: =Q21+P21 -> 8507674000 | S21: 2000 | T21: 3500 | U21: =IFERROR(INDEX('VSL and Injuries'!$G$21:$G$24,MATCH($AE21,'VSL and Injuries'!$A$21:$A$24,0)),"") -> 0.16094 | V21: =AK21*'VSL and Injuries'!$K$6 -> 25875000000 | W21: =S21*'VSL and Injuries'!$B$4+T21*'VSL and Injuries'!$B$4*U21 -> 36398718000 | X21: =W21+V21 -> 62273718000 | Y21: S017; S018; S029; S032 | Z21: Same aircraft-as-weapon mechanism as AV-05b with a cargo airframe: no passenger load, so onboard casualties minimal and total casualties driven by the ground target. Cargo aircraft may carry larger long-haul fuel load, kept in the high case. | AA21: No observed cargo aircraft-as-weapon event; scale inferred from the passenger aircraft-as-weapon mechanism and ground-target analogs. Conditional consequence only; likelihood not modeled. | AB21: On or after 2001-09-11 (ATSA regime change) | AC21: Exception taken: ground-impact mechanism inferred from 9/11 consequence physics, applied to cargo airframe. Recorded per Section 4.4. | AD21: Ground-target structural analogs used for consequence scale only; cargo-specific fuel-load analogs for property. | AE21: Blast (primary/secondary/quaternary) | AI21: 300000000 | AJ21: 3000000000 | AK21: 25000000000

Sheet Target Inputs
A1: Consequence Target Archetype Inputs
A3: Target | B3: Scope | C3: Minimum Material Outage (h) | D3: P50 Restoration (h) | E3: P90 Restoration (h) | F3: Confidence | G3: Low Deaths | H3: Low Injuries | I3: Low Injury Fraction | J3: Low Infrastructure Damage | K3: Low Daily Indirect Loss | L3: Best Deaths | M3: Best Injuries | N3: Best Injury Fraction | O3: Best Infrastructure Damage | P3: Best Daily Indirect Loss | Q3: High Deaths | R3: High Injuries | S3: High Injury Fraction | T3: High Infrastructure Damage | U3: High Daily Indirect Loss | V3: Source IDs | W3: Assumptions | X3: Regulatory-Delay Days (CAO/site-control/pressure-restriction) | Y3: Effective P90 Restoration (h)
A4: Pipeline Segment | B4: Representative hazardous-liquid or natural-gas transmission segment | C4: 24 | D4: 72 | E4: 336 | F4: Moderate-Low | G4: 0 | H4: 1 | I4: 0.02 | J4: 2000000 | K4: 5000000 | L4: 1 | M4: 5 | N4: 0.05 | O4: 15000000 | P4: 25000000 | Q4: 5 | R4: 20 | S4: 0.12 | T4: 100000000 | U4: 100000000 | V4: S017; S029; S030; S031 | W4: Daily indirect loss represents affected commodity value, substitution, curtailment, and dependent-sector disruption; excludes price-spike transfers. | X4: 20 | Y4: =E4+X4*24 -> 816
A5: Pump Station | B5: Representative liquid-pipeline pump station | C5: 12 | D5: 48 | E5: 240 | F5: Low | G5: 0 | H5: 1 | I5: 0.02 | J5: 1000000 | K5: 3000000 | L5: 1 | M5: 4 | N5: 0.05 | O5: 8000000 | P5: 15000000 | Q5: 4 | R5: 15 | S5: 0.12 | T5: 50000000 | U5: 60000000 | V5: S017; S029; S031 | W5: Assumes partial rerouting/storage capability in low and central cases; no system-specific topology is embedded. | X5: 10 | Y5: =E5+X5*24 -> 480
A6: Compressor Station | B6: Representative natural-gas compressor station | C6: 12 | D6: 72 | E6: 336 | F6: Low | G6: 0 | H6: 1 | I6: 0.02 | J6: 2000000 | K6: 4000000 | L6: 1 | M6: 5 | N6: 0.05 | O6: 12000000 | P6: 20000000 | Q6: 5 | R6: 20 | S6: 0.12 | T6: 75000000 | U6: 80000000 | V6: S017; S029; S031 | W6: Indirect loss depends on season, storage, network redundancy, affected customers, and gas-fired generation exposure. | X6: 20 | Y6: =E6+X6*24 -> 816
A7: Airport Terminal | B7: Representative large-hub passenger terminal or major terminal complex | C7: 4 | D7: 24 | E7: 168 | F7: Moderate-Low | G7: 0 | H7: 5 | I7: 0.025 | J7: 25000000 | K7: 5000000 | L7: 5 | M7: 50 | N7: 0.05 | O7: 200000000 | P7: 40000000 | Q7: 30 | R7: 250 | S7: 0.12 | T7: 1000000000 | U7: 200000000 | V7: S007; S019; S032; S033 | W7: Daily indirect loss includes displaced aviation activity, passenger delay, airport concessions, air cargo, and visitor effects; not airport-specific. | X7: 5 | Y7: =E7+X7*24 -> 288
A8: Freight Rail | B8: Representative nationally significant freight-rail corridor, bridge, tunnel, yard, or intermodal node | C8: 12 | D8: 72 | E8: 336 | F8: Moderate-Low | G8: 0 | H8: 1 | I8: 0.02 | J8: 2000000 | K8: 2000000 | L8: 1 | M8: 8 | N8: 0.05 | O8: 20000000 | P8: 15000000 | Q8: 10 | R8: 50 | S8: 0.12 | T8: 150000000 | U8: 75000000 | V8: S018; S020; S034 | W8: Indirect loss reflects delayed/lost freight value and dependent production; substitute routing is represented only through the range. | X8: 10 | Y8: =E8+X8*24 -> 576
A10: Regulatory reality note | B10: Engineering P90 restoration understates outage for regulated assets. Effective P90 adds the federal regulatory lifecycle (NTSB site control, PHMSA Corrective Action Order, metallurgical/forensic testing, and mandatory post-restart pressure restrictions). Danville PIR22002 confirms multi-week to multi-month effective outage for a major transmission segment.

Sheet Duration Factors
A1: Outage Duration and Escalation Factors
A3: Duration Label | B3: Hours | C3: Days | D3: Escalation / Buffer Factor | E3: Regulatory-Delay Add-On (days) | F3: Basis | G3: Effective Outage Days (eng + regulatory)
A4: 4 hours | B4: 4 | C4: 0.16666667 | D4: 0.35 | E4: 0 | F4: Minor; no formal hold | G4: =C4+E4 -> 0.16666667
A5: 12 hours | B5: 12 | C5: 0.5 | D5: 0.55 | E5: 0 | F5: Minor; no formal hold | G5: =C5+E5 -> 0.5
A6: 1 day | B6: 24 | C6: 1 | D6: 0.7 | E6: 0 | F6: Possible incident notification | G6: =C6+E6 -> 1
A7: 3 days | B7: 72 | C7: 3 | D7: 0.9 | E7: 1 | F7: NTSB/PHMSA notification; short hold | G7: =C7+E7 -> 4
A8: 7 days | B8: 168 | C8: 7 | D8: 1 | E8: 2 | F8: Site control + initial CAO | G8: =C8+E8 -> 9
A9: 14 days | B9: 336 | C9: 14 | D9: 1.1 | E9: 3 | F9: CAO + metallurgical/forensic testing | G9: =C9+E9 -> 17
A10: 30 days | B10: 720 | C10: 30 | D10: 1.2 | E10: 5 | F10: CAO + mandatory post-restart pressure restriction ramp | G10: =C10+E10 -> 35
A11: 45 days | B11: 1080 | C11: 45 | D11: 1.3 | E11: 10 | F11: Prolonged CAO; extensive replacement + phased restart | G11: =C11+E11 -> 55
A12: 90 days | B12: 2160 | C12: 90 | D12: 1.4 | E12: 20 | F12: Full CAO lifecycle; hydro-test + regulator sign-off before full pressure | G12: =C12+E12 -> 110
A13: Escalation / buffer factor | B13: Represents inventories, linepack, rerouting, schedule recovery, and increasing cascade severity as outages persist.
A14: Use | B14: Multiply daily indirect loss by outage days and this factor. Replace with target-specific recovery curves when available.
A15: Regulatory-delay add-on | B15: Days added to engineering restoration for forensic hold, NTSB site control, PHMSA Corrective Action Orders (CAOs), and mandatory post-restart pressure restrictions. The Danville PIR22002 transmission rupture confirms that a 14-day cap for a major pipeline is an engineering fiction once the regulatory lifecycle is included.
A16: Use | B16: Multiply daily indirect loss by EFFECTIVE outage days (column G) and the escalation/buffer factor. Replace with target-specific recovery + regulatory curves when available.

Sheet Consequence Targets
A1: First- and Second-Order Consequences by Target and Outage Duration
A3: Target | B3: Outage | C3: Hours | D3: Days | E3: Escalation Factor | F3: Confidence | G3: Low Deaths | H3: Low Injuries | I3: Low Injury Fraction | J3: Low Infrastructure Damage | K3: Low Daily Indirect | L3: Low First Order | M3: Low Second Order | N3: Low Total | O3: Best Deaths | P3: Best Injuries | Q3: Best Injury Fraction | R3: Best Infrastructure Damage | S3: Best Daily Indirect | T3: Best First Order | U3: Best Second Order | V3: Best Total | W3: High Deaths | X3: High Injuries | Y3: High Injury Fraction | Z3: High Infrastructure Damage | AA3: High Daily Indirect | AB3: High First Order | AC3: High Second Order | AD3: High Total | AE3: Source IDs | AF3: Assumptions | AG3: Effective Outage Days (eng + regulatory)
A4: Pipeline Segment | B4: 4 hours | C4: 4 | D4: =IFERROR(INDEX('Duration Factors'!$C$4:$C$12,MATCH($B4,'Duration Factors'!$A$4:$A$12,0)),"") -> 0.16666667 | E4: =IFERROR(INDEX('Duration Factors'!$D$4:$D$12,MATCH($B4,'Duration Factors'!$A$4:$A$12,0)),"") -> 0.35 | F4: Moderate-Low | G4: ='Target Inputs'!G4 -> 0 | H4: ='Target Inputs'!H4 -> 1 | I4: ='Target Inputs'!I4 -> 0.02 | J4: ='Target Inputs'!J4 -> 2000000 | K4: ='Target Inputs'!K4 -> 5000000 | L4: =G4*'VSL and Injuries'!$B$4+H4*'VSL and Injuries'!$B$4*I4+J4*'VSL and Injuries'!$K$6 -> 2354000 | M4: =K4*'VSL and Injuries'!$K$6*$AG4*E4 -> 301875 | N4: =L4+M4 -> 2655875 | O4: ='Target Inputs'!L4 -> 1 | P4: ='Target Inputs'!M4 -> 5 | Q4: ='Target Inputs'!N4 -> 0.05 | R4: ='Target Inputs'!O4 -> 15000000 | S4: ='Target Inputs'!P4 -> 25000000 | T4: =O4*'VSL and Injuries'!$B$4+P4*'VSL and Injuries'!$B$4*Q4+R4*'VSL and Injuries'!$K$6 -> 33275000 | U4: =S4*'VSL and Injuries'!$K$6*$AG4*E4 -> 1509375 | V4: =T4+U4 -> 34784375 | W4: ='Target Inputs'!Q4 -> 5 | X4: ='Target Inputs'!R4 -> 20 | Y4: ='Target Inputs'!S4 -> 0.12 | Z4: ='Target Inputs'!T4 -> 100000000 | AA4: ='Target Inputs'!U4 -> 100000000 | AB4: =W4*'VSL and Injuries'!$B$4+X4*'VSL and Injuries'!$B$4*Y4+Z4*'VSL and Injuries'!$K$6 -> 208580000 | AC4: =AA4*'VSL and Injuries'!$K$6*$AG4*E4 -> 6037500 | AD4: =AB4+AC4 -> 214617500 | AE4: S017; S029; S030; S031 | AF4: Daily indirect loss represents affected commodity value, substitution, curtailment, and dependent-sector disruption; excludes price-spike transfers. | AG4: =IFERROR(INDEX('Duration Factors'!$G$4:$G$12,MATCH($B4,'Duration Factors'!$A$4:$A$12,0)),"") -> 0.16666667
A5: Pipeline Segment | B5: 12 hours | C5: 12 | D5: =IFERROR(INDEX('Duration Factors'!$C$4:$C$12,MATCH($B5,'Duration Factors'!$A$4:$A$12,0)),"") -> 0.5 | E5: =IFERROR(INDEX('Duration Factors'!$D$4:$D$12,MATCH($B5,'Duration Factors'!$A$4:$A$12,0)),"") -> 0.55 | F5: Moderate-Low | G5: ='Target Inputs'!G4 -> 0 | H5: ='Target Inputs'!H4 -> 1 | I5: ='Target Inputs'!I4 -> 0.02 | J5: ='Target Inputs'!J4 -> 2000000 | K5: ='Target Inputs'!K4 -> 5000000 | L5: =G5*'VSL and Injuries'!$B$4+H5*'VSL and Injuries'!$B$4*I5+J5*'VSL and Injuries'!$K$6 -> 2354000 | M5: =K5*'VSL and Injuries'!$K$6*$AG5*E5 -> 1423125 | N5: =L5+M5 -> 3777125 | O5: ='Target Inputs'!L4 -> 1 | P5: ='Target Inputs'!M4 -> 5 | Q5: ='Target Inputs'!N4 -> 0.05 | R5: ='Target Inputs'!O4 -> 15000000 | S5: ='Target Inputs'!P4 -> 25000000 | T5: =O5*'VSL and Injuries'!$B$4+P5*'VSL and Injuries'!$B$4*Q5+R5*'VSL and Injuries'!$K$6 -> 33275000 | U5: =S5*'VSL and Injuries'!$K$6*$AG5*E5 -> 7115625 | V5: =T5+U5 -> 40390625 | W5: ='Target Inputs'!Q4 -> 5 | X5: ='Target Inputs'!R4 -> 20 | Y5: ='Target Inputs'!S4 -> 0.12 | Z5: ='Target Inputs'!T4 -> 100000000 | AA5: ='Target Inputs'!U4 -> 100000000 | AB5: =W5*'VSL and Injuries'!$B$4+X5*'VSL and Injuries'!$B$4*Y5+Z5*'VSL and Injuries'!$K$6 -> 208580000 | AC5: =AA5*'VSL and Injuries'!$K$6*$AG5*E5 -> 28462500 | AD5: =AB5+AC5 -> 237042500 | AE5: S017; S029; S030; S031 | AF5: Daily indirect loss represents affected commodity value, substitution, curtailment, and dependent-sector disruption; excludes price-spike transfers. | AG5: =IFERROR(INDEX('Duration Factors'!$G$4:$G$12,MATCH($B5,'Duration Factors'!$A$4:$A$12,0)),"") -> 0.5
A6: Pipeline Segment | B6: 1 day | C6: 24 | D6: =IFERROR(INDEX('Duration Factors'!$C$4:$C$12,MATCH($B6,'Duration Factors'!$A$4:$A$12,0)),"") -> 1 | E6: =IFERROR(INDEX('Duration Factors'!$D$4:$D$12,MATCH($B6,'Duration Factors'!$A$4:$A$12,0)),"") -> 0.7 | F6: Moderate-Low | G6: ='Target Inputs'!G4 -> 0 | H6: ='Target Inputs'!H4 -> 1 | I6: ='Target Inputs'!I4 -> 0.02 | J6: ='Target Inputs'!J4 -> 2000000 | K6: ='Target Inputs'!K4 -> 5000000 | L6: =G6*'VSL and Injuries'!$B$4+H6*'VSL and Injuries'!$B$4*I6+J6*'VSL and Injuries'!$K$6 -> 2354000 | M6: =K6*'VSL and Injuries'!$K$6*$AG6*E6 -> 3622500 | N6: =L6+M6 -> 5976500 | O6: ='Target Inputs'!L4 -> 1 | P6: ='Target Inputs'!M4 -> 5 | Q6: ='Target Inputs'!N4 -> 0.05 | R6: ='Target Inputs'!O4 -> 15000000 | S6: ='Target Inputs'!P4 -> 25000000 | T6: =O6*'VSL and Injuries'!$B$4+P6*'VSL and Injuries'!$B$4*Q6+R6*'VSL and Injuries'!$K$6 -> 33275000 | U6: =S6*'VSL and Injuries'!$K$6*$AG6*E6 -> 18112500 | V6: =T6+U6 -> 51387500 | W6: ='Target Inputs'!Q4 -> 5 | X6: ='Target Inputs'!R4 -> 20 | Y6: ='Target Inputs'!S4 -> 0.12 | Z6: ='Target Inputs'!T4 -> 100000000 | AA6: ='Target Inputs'!U4 -> 100000000 | AB6: =W6*'VSL and Injuries'!$B$4+X6*'VSL and Injuries'!$B$4*Y6+Z6*'VSL and Injuries'!$K$6 -> 208580000 | AC6: =AA6*'VSL and Injuries'!$K$6*$AG6*E6 -> 72450000 | AD6: =AB6+AC6 -> 281030000 | AE6: S017; S029; S030; S031 | AF6: Daily indirect loss represents affected commodity value, substitution, curtailment, and dependent-sector disruption; excludes price-spike transfers. | AG6: =IFERROR(INDEX('Duration Factors'!$G$4:$G$12,MATCH($B6,'Duration Factors'!$A$4:$A$12,0)),"") -> 1
A7: Pipeline Segment | B7: 3 days | C7: 72 | D7: =IFERROR(INDEX('Duration Factors'!$C$4:$C$12,MATCH($B7,'Duration Factors'!$A$4:$A$12,0)),"") -> 3 | E7: =IFERROR(INDEX('Duration Factors'!$D$4:$D$12,MATCH($B7,'Duration Factors'!$A$4:$A$12,0)),"") -> 0.9 | F7: Moderate-Low | G7: ='Target Inputs'!G4 -> 0 | H7: ='Target Inputs'!H4 -> 1 | I7: ='Target Inputs'!I4 -> 0.02 | J7: ='Target Inputs'!J4 -> 2000000 | K7: ='Target Inputs'!K4 -> 5000000 | L7: =G7*'VSL and Injuries'!$B$4+H7*'VSL and Injuries'!$B$4*I7+J7*'VSL and Injuries'!$K$6 -> 2354000 | M7: =K7*'VSL and Injuries'!$K$6*$AG7*E7 -> 18630000 | N7: =L7+M7 -> 20984000 | O7: ='Target Inputs'!L4 -> 1 | P7: ='Target Inputs'!M4 -> 5 | Q7: ='Target Inputs'!N4 -> 0.05 | R7: ='Target Inputs'!O4 -> 15000000 | S7: ='Target Inputs'!P4 -> 25000000 | T7: =O7*'VSL and Injuries'!$B$4+P7*'VSL and Injuries'!$B$4*Q7+R7*'VSL and Injuries'!$K$6 -> 33275000 | U7: =S7*'VSL and Injuries'!$K$6*$AG7*E7 -> 93150000 | V7: =T7+U7 -> 126425000 | W7: ='Target Inputs'!Q4 -> 5 | X7: ='Target Inputs'!R4 -> 20 | Y7: ='Target Inputs'!S4 -> 0.12 | Z7: ='Target Inputs'!T4 -> 100000000 | AA7: ='Target Inputs'!U4 -> 100000000 | AB7: =W7*'VSL and Injuries'!$B$4+X7*'VSL and Injuries'!$B$4*Y7+Z7*'VSL and Injuries'!$K$6 -> 208580000 | AC7: =AA7*'VSL and Injuries'!$K$6*$AG7*E7 -> 372600000 | AD7: =AB7+AC7 -> 581180000 | AE7: S017; S029; S030; S031 | AF7: Daily indirect loss represents affected commodity value, substitution, curtailment, and dependent-sector disruption; excludes price-spike transfers. | AG7: =IFERROR(INDEX('Duration Factors'!$G$4:$G$12,MATCH($B7,'Duration Factors'!$A$4:$A$12,0)),"") -> 4
